<mujoco model="Objs">
  <worldbody>
  <!--Grasped Object-->
      <body mocap='true' name="pourcube" pos="0.1 0.62 1.2">
          <body name="rigid_cube">
              <joint armature="0" axis="1 0 0" damping="0" limited="true" name="box_1_x" pos="0 0 0" range="-5. 5." stiffness="0" type="slide"/>
              <joint armature="0" axis="0 1 0" damping="0" limited="true" name="box_1_y" pos="0 0 0" range="-5. 5." stiffness="0" type="slide"/>
              <joint armature="0" axis="0 0 1" damping="0" limited="true" name="box_1_z" pos="0 0 0" range="-2. 2." stiffness="0" type="slide"/>
              <joint armature="0" damping="0" name="box_1_rot" pos="0 0 0" stiffness="0" type="ball"/>
              <geom type="box" size="0.03 0.03 0.03" rgba=".5 .7 .5 1" friction="1 1 1"/>
          </body>
      </body>
       <!--fix area-->
      <body mocap='true' name="grab_obj" pos="-0.5 0.62 0.8">
          <geom type="box" size="0.2 0.2 0.02" friction="1 1 1"/>
          <geom type="box" size="0.015 0.2 0.05" pos="0.2 0 0.05" friction="1 1 1"/>
          <geom type="box" size="0.015 0.2 0.05" pos="-0.2 0 0.05" friction="1 1 1"/>
          <geom type="box" size="0.2 0.015 0.05" pos="0 -0.2 0.05" friction="1 1 1"/>
          <geom type="box" size="0.2 0.015 0.05" pos="0 0.2 0.05" friction="1 1 1"/>
      </body>
  </worldbody>

</mujoco>



