<mujoco model="ur5e schunk">
  <compiler angle="radian" meshdir="assets" autolimits="true"/>

  <default>
    <default class="ur5eL">
      <material specular="0.5" shininess="0.25"/>
      <joint axis="0 1 0" range="-6.28319 6.28319" armature="0.1"/>
      <general gaintype="fixed" biastype="affine" ctrlrange="-6.2831 6.2831" gainprm="2000" biasprm="0 -2000 -400"
        forcerange="-150 150"/>
      <default class="size3L">
        <joint armature="0.1" damping="200" />
        <position kp="10000" forcerange="-150 150" ctrllimited="true" />
        <default class="size3_limitedL">
          <joint range="-3.1415 3.1415"/>
<!--          <general ctrlrange="-3.1415 3.1415"/>-->
          <position kp="10000" ctrlrange="-3.14 3.14" ctrllimited="true" />
        </default>
      </default>
      <default class="finger">
        <joint axis="-1 0 0" type="slide" range="0 0.07"/>
        <general dyntype="none" biastype="affine" ctrlrange="0 0.07" forcerange="-150 150"/>
      </default>
      <default class="size1L">
        <joint armature="0.1" damping="50" />
<!--        <general gainprm="500" biasprm="0 -500 -100" forcerange="-28 28"/>-->
        <position kp="9000" forcerange="-28 28" />
      </default>
      <default class="visualL">
        <geom type="mesh" contype="0" conaffinity="0" group="2"/>
      </default>
      <default class="collisionL">
        <geom type="capsule" group="3"/>
        <default class="eef_collisionL">
          <geom type="cylinder"/>
        </default>
      </default>
      <site size="0.001" rgba="0.5 0.5 0.5 0.3" group="4"/>
    </default>
    <default class="ycb_viz">
	  <geom contype="0" conaffinity="0" type="mesh" mass="0"/>
    </default>
    <default class="ycb_col">
	  <geom contype="1" conaffinity="1" group="3" rgba=".4 .5 .6 1"/>
    </default>
  </default>

  <asset>
    <material class="ur5eL" name="blackL" rgba="0.033 0.033 0.033 1"/>
    <material class="ur5eL" name="jointgrayL" rgba="0.278 0.278 0.278 1"/>
    <material class="ur5eL" name="linkgrayL" rgba="0.82 0.82 0.82 1"/>
    <material class="ur5eL" name="urblueL" rgba="0.49 0.678 0.8 1"/>

    <mesh name="base_0L" file="base_0.obj"/>
    <mesh name="base_1L" file="base_1.obj"/>
    <mesh name="shoulder_0L" file="shoulder_0.obj"/>
    <mesh name="shoulder_1L" file="shoulder_1.obj"/>
    <mesh name="shoulder_2L" file="shoulder_2.obj"/>
    <mesh name="upperarm_0L" file="upperarm_0.obj"/>
    <mesh name="upperarm_1L" file="upperarm_1.obj"/>
    <mesh name="upperarm_2L" file="upperarm_2.obj"/>
    <mesh name="upperarm_3L" file="upperarm_3.obj"/>
    <mesh name="forearm_0L" file="forearm_0.obj"/>
    <mesh name="forearm_1L" file="forearm_1.obj"/>
    <mesh name="forearm_2L" file="forearm_2.obj"/>
    <mesh name="forearm_3L" file="forearm_3.obj"/>
    <mesh name="wrist1_0L" file="wrist1_0.obj"/>
    <mesh name="wrist1_1L" file="wrist1_1.obj"/>
    <mesh name="wrist1_2L" file="wrist1_2.obj"/>
    <mesh name="wrist2_0L" file="wrist2_0.obj"/>
    <mesh name="wrist2_1L" file="wrist2_1.obj"/>
    <mesh name="wrist2_2L" file="wrist2_2.obj"/>
    <mesh name="wrist3L" file="wrist3.obj"/>
    <mesh name="schunkbaseL" file="schunkbase.obj"/>

    <mesh name="006_mustard_bottle" file="assets/meshes/006_mustard_bottle.msh" scale="1 1 1"/>
    <texture name="006_mustard_bottle" type="2d" file="assets/textures/006_mustard_bottle.png"/>
    <material name="006_mustard_bottle" texture="006_mustard_bottle"/>

  </asset>

  <worldbody>
    <body mocap='true' name="LEEF" pos="0 0.1 0.75" quat="1 0 0 0">
<!--      for the chain robot ee quat is (1 -1 0 0), so if you need transfer to real robot, adapt it-->
<!--      rotation order: x>y>z -->
<!--      0.6963642 -0.664463 0.2418448 0.1227878  -90 10 30-->
<!--      0.704416 -0.704416 0.0616284 -0.0616284 -90 10 0-->
      <site name="EEFee_pos" pos="0 0 0" quat="1 0 0 0"/>
<!--                    <geom type="box" size="0.001 0.001 0.001" pos="0 0.15 0" quat="1 -1 0 0"/>-->
      <inertial mass="0.1889" pos="0 0.0771683 0" quat="1 0 0 1"
        diaginertia="0.000132134 9.90863e-05 9.90863e-05"/>
      <geom material="linkgrayL" mesh="schunkbaseL" pos="0 0 -0.14"  quat="1 1 0 0" class="visualL" rgba="0.3 0.3 0.3 0.3"/>
      <geom type="box" size="0.06 0.035 0.03" pos="0 0 -0.1" quat="1 1 0 0" rgba="0.3 0.3 0.3 1" friction="1"/>
      <body name="finger1" pos="0.08 0 0">
        <inertial mass="0.015" pos="0 0 0" diaginertia="2.375e-6 2.375e-6 7.5e-7"/>
        <joint name="finger_joint1" class="finger"/>
        <geom type="box"  size="0.008 0.05 0.014" quat="1 1 0 0" rgba="0 0 1 1" friction="1"/>
      </body>
      <body name="finger2" pos="-0.08 0 0">
        <inertial mass="0.015" pos="0 0 0" diaginertia="2.375e-6 2.375e-6 7.5e-7"/>
        <joint name="finger_joint2" class="finger" axis="1 0 0"/>
        <geom type="box" size="0.008 0.05 0.014" quat="1 1 0 0" rgba="0.5 0 0.5 1" friction="1 1 1"/>
      </body>
      <body name="bowl" pos="-0.12 0 0.1" quat="0 -1 0 0">
        <inertial pos="0 0 0" mass="1.0" diaginertia="0.0102675 0.0102675 0.00666"/>
        <site name="bowlside" pos="0.12 0 0.05" rgba="1 0 0 0.3" size="0.01"/>
        <geom type="box" size="0.13 0.13 0.02" friction="1 1 1"/>
        <geom type="box" size="0.015 0.13 0.05" pos="0.12 0 0.05" rgba="0.033 0.033 0.033 1" friction="1 1 1"/>
        <geom type="box" size="0.015 0.13 0.05" pos="-0.12 0 0.05" friction="1 1 1"/>
        <geom type="box" size="0.13 0.015 0.05" pos="0 -0.12 0.05" friction="1 1 1"/>
        <geom type="box" size="0.13 0.015 0.05" pos="0 0.12 0.05" friction="1 1 1"/>
      </body>
    </body>



<!--    <body mocap='true' name="virtual_goal" pos="0.1 0.62 1.2">-->
<!--          <body name="virtual_cube">-->
<!--              <site name="virtual_obj" pos="0 0 0"/>-->
<!--              <inertial pos="0 0 0" mass="1" diaginertia="0.0102675 0.0102675 0.00666"/>-->
<!--&lt;!&ndash;              <geom type="box" pos="0 0 0" size="0.02 0.02 0.02" rgba=".5 .7 .5 1" friction="1 1 1"/>&ndash;&gt;-->
<!--              <geom type="box" pos="0 0 0" size="0.02 0.02 0.02" rgba=".5 .7 .5 1" friction="1 1 1" contype="0" conaffinity="0"/>-->
<!--          </body>-->
<!--      </body>-->

<!--    <body mocap='true' name="LEEF" pos="0 0.1 0.75" quat="1 0 0 0">-->
<!--&lt;!&ndash;      rotation order: x>y>z &ndash;&gt;-->
<!--&lt;!&ndash;      0.6963642 -0.664463 0.2418448 0.1227878  -90 10 30&ndash;&gt;-->
<!--&lt;!&ndash;      0.704416 -0.704416 0.0616284 -0.0616284 -90 10 0&ndash;&gt;-->
<!--      <site name="EEFee_pos" pos="0 0.15 0" quat="1 -1 0 0"/>-->
<!--&lt;!&ndash;                    <geom type="box" size="0.001 0.001 0.001" pos="0 0.15 0" quat="1 -1 0 0"/>&ndash;&gt;-->
<!--      <inertial mass="0.1889" pos="0 0.0771683 0" quat="1 0 0 1"-->
<!--        diaginertia="0.000132134 9.90863e-05 9.90863e-05"/>-->
<!--      <geom material="linkgrayL" mesh="schunkbaseL" class="visualL" rgba="0.3 0.3 0.3 0.5"/>-->
<!--      <geom type="box" size="0.06 0.035 0.03" pos="0 0.035 0" rgba="0.3 0.3 0.3 0.2" friction="1"/>-->
<!--      <body name="finger1" pos="0.08 0.13 0">-->
<!--        <inertial mass="0.015" pos="0 0 0" diaginertia="2.375e-6 2.375e-6 7.5e-7"/>-->
<!--        <joint name="finger_joint1" class="finger"/>-->
<!--        <geom type="box"  size="0.008 0.05 0.014" rgba="0 0 1 1" friction="1"/>-->
<!--      </body>-->
<!--      <body name="finger2" pos="-0.08 0.13 0">-->
<!--        <inertial mass="0.015" pos="0 0 0" diaginertia="2.375e-6 2.375e-6 7.5e-7"/>-->
<!--        <joint name="finger_joint2" class="finger" axis="1 0 0"/>-->
<!--        <geom type="box" size="0.008 0.05 0.014" rgba="0.5 0 0.5 1" friction="1 1 1"/>-->
<!--      </body>-->
<!--    </body>-->


  </worldbody>
  
  <equality>
    <joint joint1="finger_joint1" joint2="finger_joint2" solimp="0.99 0.99 0.001" solref="0.005 1"/>
  </equality>
  
  <actuator>
<!--    <position class="size3L" name="shoulder_panL" joint="shoulder_pan_jointL"/>-->
<!--    <position class="size3L" name="shoulder_liftL" joint="shoulder_lift_jointL"/>-->
<!--    <position class="size3_limitedL" name="elbowL" joint="elbow_jointL"/>-->
<!--    <position class="size1L" name="wrist_1L" joint="wrist_1_jointL"/>-->
<!--    <position class="size1L" name="wrist_2L" joint="wrist_2_jointL"/>-->
<!--    <position class="size1L" name="wrist_3L" joint="wrist_3_jointL"/>-->
    <position class="finger" name="fingers" joint="finger_joint1"/>
  </actuator>
  
<!--  <sensor>-->
<!--  	<framepos objtype="site" objname="L_ft_sensor"/>-->
<!--  	<force name='Lforce' site='L_ft_sensor'/>-->
<!--  	<torque name='Ltorque' site='L_ft_sensor'/>-->
<!--  </sensor>-->

</mujoco>
