<mujoco model="ur5e schunk">
  <compiler angle="radian" meshdir="assets" autolimits="true"/>

  <default>
    <default class="ur5eL">
      <material specular="0.5" shininess="0.25"/>
      <joint axis="0 1 0" range="-6.28319 6.28319" armature="0.1"/>
      <general gaintype="fixed" biastype="affine" ctrlrange="-6.2831 6.2831" gainprm="2000" biasprm="0 -2000 -400"
        forcerange="-150 150"/>
      <default class="size3L">
        <joint armature="0.1" damping="200" />
        <position kp="10000" forcerange="-150 150" ctrllimited="true" />
        <default class="size3_limitedL">
          <joint range="-3.1415 3.1415"/>
<!--          <general ctrlrange="-3.1415 3.1415"/>-->
          <position kp="10000" ctrlrange="-3.14 3.14" ctrllimited="true" />
        </default>
      </default>
      <default class="finger">
        <joint axis="-1 0 0" type="slide" range="0 0.07"/>
        <general dyntype="none" biastype="affine" ctrlrange="0 0.07" forcerange="-150 150"/>
      </default>
      <default class="size1L">
        <joint armature="0.1" damping="50" />
<!--        <general gainprm="500" biasprm="0 -500 -100" forcerange="-28 28"/>-->
        <position kp="9000" forcerange="-28 28" />
      </default>
      <default class="visualL">
        <geom type="mesh" contype="0" conaffinity="0" group="2"/>
      </default>
      <default class="collisionL">
        <geom type="capsule" group="3"/>
        <default class="eef_collisionL">
          <geom type="cylinder"/>
        </default>
      </default>
      <site size="0.001" rgba="0.5 0.5 0.5 0.3" group="4"/>
    </default>
    <default class="ycb_col">
	  <geom contype="1" conaffinity="1" group="3" rgba=".4 .5 .6 1"/>
    </default>
    <default class="ycb_viz">
	  <geom contype="0" conaffinity="0" type="mesh" mass="0"/>
    </default>
  </default>

  <asset>
    <material class="ur5eL" name="blackL" rgba="0.033 0.033 0.033 1"/>
    <material class="ur5eL" name="jointgrayL" rgba="0.278 0.278 0.278 1"/>
    <material class="ur5eL" name="linkgrayL" rgba="0.82 0.82 0.82 1"/>
    <material class="ur5eL" name="urblueL" rgba="0.49 0.678 0.8 1"/>

    <mesh name="base_0L" file="base_0.obj"/>
    <mesh name="base_1L" file="base_1.obj"/>
    <mesh name="shoulder_0L" file="shoulder_0.obj"/>
    <mesh name="shoulder_1L" file="shoulder_1.obj"/>
    <mesh name="shoulder_2L" file="shoulder_2.obj"/>
    <mesh name="upperarm_0L" file="upperarm_0.obj"/>
    <mesh name="upperarm_1L" file="upperarm_1.obj"/>
    <mesh name="upperarm_2L" file="upperarm_2.obj"/>
    <mesh name="upperarm_3L" file="upperarm_3.obj"/>
    <mesh name="forearm_0L" file="forearm_0.obj"/>
    <mesh name="forearm_1L" file="forearm_1.obj"/>
    <mesh name="forearm_2L" file="forearm_2.obj"/>
    <mesh name="forearm_3L" file="forearm_3.obj"/>
    <mesh name="wrist1_0L" file="wrist1_0.obj"/>
    <mesh name="wrist1_1L" file="wrist1_1.obj"/>
    <mesh name="wrist1_2L" file="wrist1_2.obj"/>
    <mesh name="wrist2_0L" file="wrist2_0.obj"/>
    <mesh name="wrist2_1L" file="wrist2_1.obj"/>
    <mesh name="wrist2_2L" file="wrist2_2.obj"/>
    <mesh name="wrist3L" file="wrist3.obj"/>
    <mesh name="schunkbaseL" file="schunkbase.obj"/>

    <mesh name="006_mustard_bottle" file="assets/meshes/006_mustard_bottle.msh" scale="1 1 1"/>
    <texture name="006_mustard_bottle" type="2d" file="assets/textures/006_mustard_bottle.png"/>
    <material name="006_mustard_bottle" texture="006_mustard_bottle"/>
  </asset>

  <worldbody>
    <body name="baseL" pos="-0.5 0 0.816" quat="1 0 0 0" childclass="ur5eL">
      <inertial mass="4.0" pos="0 0 0" diaginertia="0.00443333156 0.00443333156 0.0072"/>
      <geom mesh="base_0L" material="blackL" class="visualL"/>
      <geom mesh="base_1L" material="jointgrayL" class="visualL"/>
      <body name="shoulder_linkL" pos="0 0 0.163">
        <inertial mass="3.7" pos="0 0 0" diaginertia="0.0102675 0.0102675 0.00666"/>
        <joint name="shoulder_pan_jointL" class="size3L" axis="0 0 1"/>
        <geom mesh="shoulder_0L" material="urblueL" class="visualL"/>
        <geom mesh="shoulder_1L" material="blackL" class="visualL"/>
        <geom mesh="shoulder_2L" material="jointgrayL" class="visualL"/>
        <geom class="collisionL" size="0.06 0.06" pos="0 0 -0.04"/>
        <body name="upper_arm_linkL" pos="0 0.138 0" quat="1 0 1 0">
          <inertial mass="4.393" pos="0 0 0.2125" diaginertia="0.133886 0.133886 0.0151074"/>
          <joint name="shoulder_lift_jointL" class="size3L"/>
          <geom mesh="upperarm_0L" material="linkgrayL" class="visualL"/>
          <geom mesh="upperarm_1L" material="blackL" class="visualL"/>
          <geom mesh="upperarm_2L" material="jointgrayL" class="visualL"/>
          <geom mesh="upperarm_3L" material="urblueL" class="visualL"/>
          <geom class="collisionL" pos="0 -0.04 0" quat="1 1 0 0" size="0.06 0.06"/>
          <geom class="collisionL" size="0.05 0.2" pos="0 0 0.2"/>
          <body name="forearm_linkL" pos="0 -0.131 0.425">
            <inertial mass="2.275" pos="0 0 0.196" diaginertia="0.0311796 0.0311796 0.004095"/>
            <joint name="elbow_jointL" class="size3_limitedL"/>
            <geom mesh="forearm_0L" material="urblueL" class="visualL"/>
            <geom mesh="forearm_1L" material="linkgrayL" class="visualL"/>
            <geom mesh="forearm_2L" material="blackL" class="visualL"/>
            <geom mesh="forearm_3L" material="jointgrayL" class="visualL"/>
            <geom class="collisionL" pos="0 0.08 0" quat="1 1 0 0" size="0.055 0.06"/>
            <geom class="collisionL" size="0.038 0.19" pos="0 0 0.2"/>
            <body name="wrist_1_linkL" pos="0 0 0.392" quat="1 0 1 0">
              <inertial mass="1.219" pos="0 0.127 0" diaginertia="0.0025599 0.0025599 0.0021942"/>
              <joint name="wrist_1_jointL" class="size1L"/>
              <geom mesh="wrist1_0L" material="blackL" class="visualL"/>
              <geom mesh="wrist1_1L" material="urblueL" class="visualL"/>
              <geom mesh="wrist1_2L" material="jointgrayL" class="visualL"/>
              <geom class="collisionL" pos="0 0.05 0" quat="1 1 0 0" size="0.04 0.07"/>
              <body name="wrist_2_linkL" pos="0 0.127 0">
                <inertial mass="1.219" pos="0 0 0.1" diaginertia="0.0025599 0.0025599 0.0021942"/>
                <joint name="wrist_2_jointL" axis="0 0 1" class="size1L"/>
                <geom mesh="wrist2_0L" material="blackL" class="visualL"/>
                <geom mesh="wrist2_1L" material="urblueL" class="visualL"/>
                <geom mesh="wrist2_2L" material="jointgrayL" class="visualL"/>
                <geom class="collisionL" size="0.04 0.06" pos="0 0 0.04"/>
                <geom class="collisionL" pos="0 0.02 0.1" quat="1 1 0 0" size="0.04 0.04"/>
                <body name="wrist_3_linkL" pos="0 0 0.1" quat='1 0 0 0'>
                  <inertial mass="0.1889" pos="0 0.0771683 0" quat="1 0 0 1"
                    diaginertia="0.000132134 9.90863e-05 9.90863e-05"/>
                  <joint name="wrist_3_jointL" class="size1L"/>
                  <geom material="linkgrayL" mesh="wrist3L" class="visualL"/>
                  <geom class="eef_collisionL" pos="0 0.08 0" quat="1 1 0 0" size="0.04 0.02"/>
                  <site name="attachment_siteL" pos="0 0.25 0" quat="1 0 0 0"/>
                  <site name="ee_pos" pos="0 0.1 0" quat="1 0 0 0"/>
                  <site name="L_ft_sensor" pos="0 0.1 0" rgba="1 0 0 0.3" size="0.1"/>
                  <body name="LEEF" pos="0 0.1 0">
                    <site name="EEFee_pos" pos="0 0.15 0" quat="1 -1 0 0"/>
<!--                    <geom type="box" size="0.001 0.001 0.001" pos="0 0.15 0" quat="1 -1 0 0"/>-->
                    <inertial mass="0.1889" pos="0 0.0771683 0" quat="1 0 0 1"
                      diaginertia="0.000132134 9.90863e-05 9.90863e-05"/>
                    <geom material="linkgrayL" mesh="schunkbaseL" class="visualL"/>
                    <body name="finger1" pos="0.08 0.13 0">
                      <inertial mass="0.015" pos="0 0 0" diaginertia="2.375e-6 2.375e-6 7.5e-7"/>
                      <joint name="finger_joint1" class="finger"/>
                      <geom type="box"  size="0.008 0.05 0.014" rgba="0 0 1 1" friction="1"/>
                    </body>
                    <body name="finger2" pos="-0.08 0.13 0">
                      <inertial mass="0.015" pos="0 0 0" diaginertia="2.375e-6 2.375e-6 7.5e-7"/>
                      <joint name="finger_joint2" class="finger" axis="1 0 0"/>
                      <geom type="box" size="0.008 0.05 0.014" rgba="0.5 0 0.5 1" friction="1 1 1"/>
                    </body>
                    <body name="grab_obj" pos="0 0.15 0">
                      <site name="obj_state" pos="0 0 0" quat="1 -1 0 0"/>
                      <inertial mass="1" pos="0 0 0" diaginertia="2.375e-6 2.375e-6 7.5e-7"/>
                      <geom class="ycb_viz" mesh="006_mustard_bottle" pos="0 0 -0.05" material="006_mustard_bottle"/>
                      <geom class="ycb_col" type="mesh" mesh="006_mustard_bottle" pos="0 0 -0.05" mass="0.431"/>
                    </body>
                  </body>
                </body>
              </body>
            </body>
          </body>
        </body>
      </body>
    </body>


  </worldbody>
  
  <equality>
    <joint joint1="finger_joint1" joint2="finger_joint2" solimp="0.99 0.99 0.001" solref="0.005 1"/>
  </equality>
  
  <actuator>
    <position class="size3L" name="shoulder_panL" joint="shoulder_pan_jointL"/>
    <position class="size3L" name="shoulder_liftL" joint="shoulder_lift_jointL"/>
    <position class="size3_limitedL" name="elbowL" joint="elbow_jointL"/>
    <position class="size1L" name="wrist_1L" joint="wrist_1_jointL"/>
    <position class="size1L" name="wrist_2L" joint="wrist_2_jointL"/>
    <position class="size1L" name="wrist_3L" joint="wrist_3_jointL"/>
    <position class="finger" name="fingers" joint="finger_joint1"/>
  </actuator>
  
  <sensor>
  	<framepos objtype="site" objname="L_ft_sensor"/>
  	<force name='Lforce' site='L_ft_sensor'/>
  	<torque name='Ltorque' site='L_ft_sensor'/>
  </sensor>

</mujoco>
